Workbook

Sheet Resumo
A1: Teste de sobrecarga do instrumento (A/B): ORG no Android (Samsung Galaxy A54 5G)
A2: Pergunta: medir CPU, memória e FPS dentro do próprio app compromete o desempenho? (efeito do observador)
A3: Build A = app sem medição · Build B = build do experimento (Sentry + coletor de 15 s) · medição externa via adb · 3 rodadas por build
A5: Métrica | B5: n (A) | C5: Média A | D5: Desvio padrão A | E5: n (B) | F5: Média B | G5: Desvio padrão B | H5: Diferença (B − A) | I5: Diferença relativa | J5: t de Welch | K5: Graus de liberdade (Welch) | L5: p (bicaudal)
A6: CPU média (% de um núcleo) | B6: =COUNTIF(Rodadas!$B$5:$B$10,"A") -> 3 | C6: =AVERAGEIF(Rodadas!$B$5:$B$10,"A",Rodadas!D$5:D$10) -> 11.487963 | D6: =SQRT(SUMIF(Rodadas!$B$5:$B$10,"A",Rodadas!N$5:N$10)/(B6-1)) -> 0.7279041 | E6: =COUNTIF(Rodadas!$B$5:$B$10,"B") -> 3 | F6: =AVERAGEIF(Rodadas!$B$5:$B$10,"B",Rodadas!D$5:D$10) -> 12.089661 | G6: =SQRT(SUMIF(Rodadas!$B$5:$B$10,"B",Rodadas!N$5:N$10)/(E6-1)) -> 0.58438083 | H6: =F6-C6 -> 0.6016984 | I6: =H6/C6 -> 0.052376423 | J6: =H6/SQRT(D6^2/B6+G6^2/E6) -> 1.116463 | K6: =(D6^2/B6+G6^2/E6)^2/((D6^2/B6)^2/(B6-1)+(G6^2/E6)^2/(E6-1)) -> 3.8214545 | L6: =_xlfn.BETA.DIST(K6/(K6+J6^2),K6/2,0.5,TRUE()) -> 0.32946091
A7: RSS médio (MB) | B7: =COUNTIF(Rodadas!$B$5:$B$10,"A") -> 3 | C7: =AVERAGEIF(Rodadas!$B$5:$B$10,"A",Rodadas!F$5:F$10) -> 242.14968 | D7: =SQRT(SUMIF(Rodadas!$B$5:$B$10,"A",Rodadas!O$5:O$10)/(B7-1)) -> 2.1227615 | E7: =COUNTIF(Rodadas!$B$5:$B$10,"B") -> 3 | F7: =AVERAGEIF(Rodadas!$B$5:$B$10,"B",Rodadas!F$5:F$10) -> 246.37759 | G7: =SQRT(SUMIF(Rodadas!$B$5:$B$10,"B",Rodadas!O$5:O$10)/(E7-1)) -> 4.662223 | H7: =F7-C7 -> 4.2279064 | I7: =H7/C7 -> 0.017459888 | J7: =H7/SQRT(D7^2/B7+G7^2/E7) -> 1.4294991 | K7: =(D7^2/B7+G7^2/E7)^2/((D7^2/B7)^2/(B7-1)+(G7^2/E7)^2/(E7-1)) -> 2.7950633 | L7: =_xlfn.BETA.DIST(K7/(K7+J7^2),K7/2,0.5,TRUE()) -> 0.25447884
A8: PSS final (MB) | B8: =COUNTIF(Rodadas!$B$5:$B$10,"A") -> 3 | C8: =AVERAGEIF(Rodadas!$B$5:$B$10,"A",Rodadas!H$5:H$10) -> 148.935 | D8: =SQRT(SUMIF(Rodadas!$B$5:$B$10,"A",Rodadas!P$5:P$10)/(B8-1)) -> 9.4616039 | E8: =COUNTIF(Rodadas!$B$5:$B$10,"B") -> 3 | F8: =AVERAGEIF(Rodadas!$B$5:$B$10,"B",Rodadas!H$5:H$10) -> 147.50174 | G8: =SQRT(SUMIF(Rodadas!$B$5:$B$10,"B",Rodadas!P$5:P$10)/(E8-1)) -> 11.229028 | H8: =F8-C8 -> -1.4332587 | I8: =H8/C8 -> -0.009623384 | J8: =H8/SQRT(D8^2/B8+G8^2/E8) -> -0.16906267 | K8: =(D8^2/B8+G8^2/E8)^2/((D8^2/B8)^2/(B8-1)+(G8^2/E8)^2/(E8-1)) -> 3.8881535 | L8: =_xlfn.BETA.DIST(K8/(K8+J8^2),K8/2,0.5,TRUE()) -> 0.87417653
A10: Leitura (06/10/2026)
A11: A medição dentro do app acrescentou cerca de 0,6 ponto percentual de CPU e 4 MB de memória residente. As diferenças não são significativas (p > 0,05) e têm a mesma ordem de grandeza da variação entre rodadas do mesmo build.
A13: Observações
A14: CPU em % de um núcleo: 100% = um núcleo inteiro ocupado (o A54 tem 8 núcleos).
A15: p bicaudal da distribuição t com os graus de liberdade de Welch (fracionários): p = BETA.DIST(gl ÷ (gl + t²); gl ÷ 2; 0,5; VERDADEIRO). A função DIST.T.BC (T.DIST.2T) do Excel truncaria os graus de liberdade.
A16: Com 3 rodadas por build o poder estatístico é baixo: o resultado indica sobrecarga pequena e indistinguível da variação natural, e não sobrecarga zero.
A17: O instrumento está nas builds do experimento das duas plataformas, então seu custo não favorece Android nem iOS na comparação.
A18: Condições: estado térmico 0 em todas as rodadas; bateria de 66 a 69% (carregando pelo USB, igual para A e B); tela a 60 Hz; app parado na lista de Pedidos.
A19: Rastreabilidade: dados brutos nas abas 'CPU por amostra' e 'RSS'; resultados por rodada na aba 'Rodadas'; procedimento na aba 'Método'.

Sheet Rodadas
A1: Resultados por rodada: 6 rodadas na ordem A B A B B A; em cada uma, 180 amostras de CPU (~195 s) sem toque, após 60 s de estabilização
A2: Build A = app sem medição (sem Sentry e sem coletor) · Build B = build do experimento (Sentry com tracing + coletor de 15 s)
A4: Rodada | B4: Build | C4: Início da medição (horário de Brasília) | D4: CPU média (% de um núcleo) | E4: CPU máxima entre duas amostras (% de um núcleo) | F4: RSS médio (MB) | G4: PSS final (kB, dumpsys) | H4: PSS final (MB) | I4: Duração medida (s) | J4: Amostras de CPU | K4: App em primeiro plano | L4: Estado térmico (0 = normal) | M4: Bateria (%) | N4: Aux.: (CPU − média do build)² | O4: Aux.: (RSS − média do build)² | P4: Aux.: (PSS − média do build)²
A5: 1 | B5: A | C5: 06/10/2026, 19:49:18 | D5: =('CPU por amostra'!F184-'CPU por amostra'!F5)/'CPU por amostra'!$G$2/('CPU por amostra'!D184-'CPU por amostra'!D5)*100 -> 10.786997 | E5: =MAX('CPU por amostra'!G5:G184) -> 28.077155 | F5: =AVERAGE(RSS!F5:F22) -> 243.39206 | G5: 144006 | H5: =G5*1024/1000000 -> 147.46214 | I5: ='CPU por amostra'!D184-'CPU por amostra'!D5 -> 195.42047 | J5: =COUNT('CPU por amostra'!D5:D184) -> 180 | K5: sim | L5: 0 | M5: 66 | N5: =(D5-AVERAGEIF($B$5:$B$10,B5,D$5:D$10))^2 -> 0.49135299 | O5: =(F5-AVERAGEIF($B$5:$B$10,B5,F$5:F$10))^2 -> 1.5435018 | P5: =(H5-AVERAGEIF($B$5:$B$10,B5,H$5:H$10))^2 -> 2.1692969
A6: 2 | B6: B | C6: 06/10/2026, 19:54:58 | D6: =('CPU por amostra'!F364-'CPU por amostra'!F185)/'CPU por amostra'!$G$2/('CPU por amostra'!D364-'CPU por amostra'!D185)*100 -> 12.153977 | E6: =MAX('CPU por amostra'!G185:G364) -> 29.638785 | F6: =AVERAGE(RSS!F23:F40) -> 248.57077 | G6: 156630 | H6: =G6*1024/1000000 -> 160.38912 | I6: ='CPU por amostra'!D364-'CPU por amostra'!D185 -> 195.73841 | J6: =COUNT('CPU por amostra'!D185:D364) -> 180 | K6: sim | L6: 0 | M6: 66 | N6: =(D6-AVERAGEIF($B$5:$B$10,B6,D$5:D$10))^2 -> 0.0041364763 | O6: =(F6-AVERAGEIF($B$5:$B$10,B6,F$5:F$10))^2 -> 4.8100405 | P6: =(H6-AVERAGEIF($B$5:$B$10,B6,H$5:H$10))^2 -> 166.0846
A7: 3 | B7: A | C7: 06/10/2026, 20:04:35 | D7: =('CPU por amostra'!F544-'CPU por amostra'!F365)/'CPU por amostra'!$G$2/('CPU por amostra'!D544-'CPU por amostra'!D365)*100 -> 12.240104 | E7: =MAX('CPU por amostra'!G365:G544) -> 30.767976 | F7: =AVERAGE(RSS!F41:F58) -> 239.6986 | G7: 137008 | H7: =G7*1024/1000000 -> 140.29619 | I7: ='CPU por amostra'!D544-'CPU por amostra'!D365 -> 196.56695 | J7: =COUNT('CPU por amostra'!D365:D544) -> 180 | K7: sim | L7: 0 | M7: 67 | N7: =(D7-AVERAGEIF($B$5:$B$10,B7,D$5:D$10))^2 -> 0.56571681 | O7: =(F7-AVERAGEIF($B$5:$B$10,B7,F$5:F$10))^2 -> 6.0077772 | P7: =(H7-AVERAGEIF($B$5:$B$10,B7,H$5:H$10))^2 -> 74.628958
A8: 4 | B8: B | C8: 06/10/2026, 20:09:48 | D8: =('CPU por amostra'!F724-'CPU por amostra'!F545)/'CPU por amostra'!$G$2/('CPU por amostra'!D724-'CPU por amostra'!D545)*100 -> 11.475783 | E8: =MAX('CPU por amostra'!G545:G724) -> 31.666767 | F8: =AVERAGE(RSS!F59:F76) -> 241.0232 | G8: 138959 | H8: =G8*1024/1000000 -> 142.29402 | I8: ='CPU por amostra'!D724-'CPU por amostra'!D545 -> 194.84509 | J8: =COUNT('CPU por amostra'!D545:D724) -> 180 | K8: sim | L8: 0 | M8: 68 | N8: =(D8-AVERAGEIF($B$5:$B$10,B8,D$5:D$10))^2 -> 0.37684632 | O8: =(F8-AVERAGEIF($B$5:$B$10,B8,F$5:F$10))^2 -> 28.669409 | P8: =(H8-AVERAGEIF($B$5:$B$10,B8,H$5:H$10))^2 -> 27.120375
A9: 5 | B9: B | C9: 06/10/2026, 20:15:00 | D9: =('CPU por amostra'!F904-'CPU por amostra'!F725)/'CPU por amostra'!$G$2/('CPU por amostra'!D904-'CPU por amostra'!D725)*100 -> 12.639224 | E9: =MAX('CPU por amostra'!G725:G904) -> 36.053474 | F9: =AVERAGE(RSS!F77:F94) -> 249.53879 | G9: 136545 | H9: =G9*1024/1000000 -> 139.82208 | I9: ='CPU por amostra'!D904-'CPU por amostra'!D725 -> 196.53106 | J9: =COUNT('CPU por amostra'!D725:D904) -> 180 | K9: sim | L9: 0 | M9: 68 | N9: =(D9-AVERAGEIF($B$5:$B$10,B9,D$5:D$10))^2 -> 0.30201911 | O9: =(F9-AVERAGEIF($B$5:$B$10,B9,F$5:F$10))^2 -> 9.9931967 | P9: =(H9-AVERAGEIF($B$5:$B$10,B9,H$5:H$10))^2 -> 58.977157
A10: 6 | B10: A | C10: 06/10/2026, 20:20:35 | D10: =('CPU por amostra'!F1084-'CPU por amostra'!F905)/'CPU por amostra'!$G$2/('CPU por amostra'!D1084-'CPU por amostra'!D905)*100 -> 11.436787 | E10: =MAX('CPU por amostra'!G905:G1084) -> 32.225207 | F10: =AVERAGE(RSS!F95:F112) -> 243.35838 | G10: 155319 | H10: =G10*1024/1000000 -> 159.04666 | I10: ='CPU por amostra'!D1084-'CPU por amostra'!D905 -> 196.12152 | J10: =COUNT('CPU por amostra'!D905:D1084) -> 180 | K10: sim | L10: 0 | M10: 69 | N10: =(D10-AVERAGEIF($B$5:$B$10,B10,D$5:D$10))^2 -> 0.0026189547 | O10: =(F10-AVERAGEIF($B$5:$B$10,B10,F$5:F$10))^2 -> 1.4609539 | P10: =(H10-AVERAGEIF($B$5:$B$10,B10,H$5:H$10))^2 -> 102.24564

Sheet CPU por amostra
A1: Dados brutos de CPU: /proc/<pid>/stat a cada ~1,1 s (pausa de 1 s + tempo da leitura), lido pelo shell do adb, fora do app
A2: utime+stime em ticks do kernel; CPU no intervalo = Δticks ÷ CLK_TCK ÷ Δt × 100 (% de um núcleo) | F2: CLK_TCK (ticks/s): | G2: 100
A4: Rodada | B4: Build | C4: Amostra | D4: Instante (s, relógio do aparelho) | E4: Tempo desde o início (s) | F4: utime+stime (ticks) | G4: CPU no intervalo (% de um núcleo)
A5: 1 | B5: A | C5: 1 | D5: 1.791327e+09 | E5: =D5-D5 -> 0 | F5: 813
A6: 1 | B6: A | C6: 2 | D6: 1.791327e+09 | E6: =D6-D5 -> 1.0757465 | F6: 819 | G6: =(F6-F5)/$G$2/(D6-D5)*100 -> 5.577522
A7: 1 | B7: A | C7: 3 | D7: 1.791327e+09 | E7: =D7-D5 -> 2.1720557 | F7: 829 | G7: =(F7-F6)/$G$2/(D7-D6)*100 -> 9.1215144
A8: 1 | B8: A | C8: 4 | D8: 1.791327e+09 | E8: =D8-D5 -> 3.2443593 | F8: 836 | G8: =(F8-F7)/$G$2/(D8-D7)*100 -> 6.5280024
A9: 1 | B9: A | C9: 5 | D9: 1.791327e+09 | E9: =D9-D5 -> 4.3247921 | F9: 846 | G9: =(F9-F8)/$G$2/(D9-D8)*100 -> 9.2555494
A10: 1 | B10: A | C10: 6 | D10: 1.791327e+09 | E10: =D10-D5 -> 5.4137423 | F10: 853 | G10: =(F10-F9)/$G$2/(D10-D9)*100 -> 6.4282097
A11: 1 | B11: A | C11: 7 | D11: 1.791327e+09 | E11: =D11-D5 -> 6.5147753 | F11: 864 | G11: =(F11-F10)/$G$2/(D11-D10)*100 -> 9.9906182
A12: 1 | B12: A | C12: 8 | D12: 1.791327e+09 | E12: =D12-D5 -> 7.6091275 | F12: 875 | G12: =(F12-F11)/$G$2/(D12-D11)*100 -> 10.051608
A13: 1 | B13: A | C13: 9 | D13: 1.791327e+09 | E13: =D13-D5 -> 8.6745105 | F13: 886 | G13: =(F13-F12)/$G$2/(D13-D12)*100 -> 10.324926
A14: 1 | B14: A | C14: 10 | D14: 1.791327e+09 | E14: =D14-D5 -> 9.7774773 | F14: 897 | G14: =(F14-F13)/$G$2/(D14-D13)*100 -> 9.9731018
A15: 1 | B15: A | C15: 11 | D15: 1.791327e+09 | E15: =D15-D5 -> 10.888206 | F15: 904 | G15: =(F15-F14)/$G$2/(D15-D14)*100 -> 6.3021688
A16: 1 | B16: A | C16: 12 | D16: 1.791327e+09 | E16: =D16-D5 -> 11.969953 | F16: 925 | G16: =(F16-F15)/$G$2/(D16-D15)*100 -> 19.413045
A17: 1 | B17: A | C17: 13 | D17: 1.791327e+09 | E17: =D17-D5 -> 13.062026 | F17: 941 | G17: =(F17-F16)/$G$2/(D17-D16)*100 -> 14.651033
A18: 1 | B18: A | C18: 14 | D18: 1.791327e+09 | E18: =D18-D5 -> 14.162361 | F18: 951 | G18: =(F18-F17)/$G$2/(D18-D17)*100 -> 9.0881423
A19: 1 | B19: A | C19: 15 | D19: 1.791327e+09 | E19: =D19-D5 -> 15.267069 | F19: 961 | G19: =(F19-F18)/$G$2/(D19-D18)*100 -> 9.0521642
A20: 1 | B20: A | C20: 16 | D20: 1.791327e+09 | E20: =D20-D5 -> 16.335629 | F20: 966 | G20: =(F20-F19)/$G$2/(D20-D19)*100 -> 4.6791949
A21: 1 | B21: A | C21: 17 | D21: 1.791327e+09 | E21: =D21-D5 -> 17.41058 | F21: 977 | G21: =(F21-F20)/$G$2/(D21-D20)*100 -> 10.233025
A22: 1 | B22: A | C22: 18 | D22: 1.791327e+09 | E22: =D22-D5 -> 18.489649 | F22: 988 | G22: =(F22-F21)/$G$2/(D22-D21)*100 -> 10.193971
A23: 1 | B23: A | C23: 19 | D23: 1.791327e+09 | E23: =D23-D5 -> 19.592717 | F23: 994 | G23: =(F23-F22)/$G$2/(D23-D22)*100 -> 5.4393752
A24: 1 | B24: A | C24: 20 | D24: 1.791327e+09 | E24: =D24-D5 -> 20.677808 | F24: 1005 | G24: =(F24-F23)/$G$2/(D24-D23)*100 -> 10.137402
A25: 1 | B25: A | C25: 21 | D25: 1.791327e+09 | E25: =D25-D5 -> 21.776884 | F25: 1015 | G25: =(F25-F24)/$G$2/(D25-D24)*100 -> 9.0985477
A26: 1 | B26: A | C26: 22 | D26: 1.791327e+09 | E26: =D26-D5 -> 22.861223 | F26: 1025 | G26: =(F26-F25)/$G$2/(D26-D25)*100 -> 9.222211
A27: 1 | B27: A | C27: 23 | D27: 1.791327e+09 | E27: =D27-D5 -> 23.89525 | F27: 1032 | G27: =(F27-F26)/$G$2/(D27-D26)*100 -> 6.7696454
A28: 1 | B28: A | C28: 24 | D28: 1.791327e+09 | E28: =D28-D5 -> 24.948743 | F28: 1055 | G28: =(F28-F27)/$G$2/(D28-D27)*100 -> 21.832133
A29: 1 | B29: A | C29: 25 | D29: 1.791327e+09 | E29: =D29-D5 -> 26.030579 | F29: 1066 | G29: =(F29-F28)/$G$2/(D29-D28)*100 -> 10.1679
A30: 1 | B30: A | C30: 26 | D30: 1.791327e+09 | E30: =D30-D5 -> 27.135588 | F30: 1077 | G30: =(F30-F29)/$G$2/(D30-D29)*100 -> 9.9546715
A31: 1 | B31: A | C31: 27 | D31: 1.791327e+09 | E31: =D31-D5 -> 28.23994 | F31: 1087 | G31: =(F31-F30)/$G$2/(D31-D30)*100 -> 9.0550859
A32: 1 | B32: A | C32: 28 | D32: 1.791327e+09 | E32: =D32-D5 -> 29.326083 | F32: 1095 | G32: =(F32-F31)/$G$2/(D32-D31)*100 -> 7.3655093
A33: 1 | B33: A | C33: 29 | D33: 1.791327e+09 | E33: =D33-D5 -> 30.383896 | F33: 1106 | G33: =(F33-F32)/$G$2/(D33-D32)*100 -> 10.398821
A34: 1 | B34: A | C34: 30 | D34: 1.791327e+09 | E34: =D34-D5 -> 31.497523 | F34: 1119 | G34: =(F34-F33)/$G$2/(D34-D33)*100 -> 11.673568
A35: 1 | B35: A | C35: 31 | D35: 1.791327e+09 | E35: =D35-D5 -> 32.642383 | F35: 1131 | G35: =(F35-F34)/$G$2/(D35-D34)*100 -> 10.481624
A36: 1 | B36: A | C36: 32 | D36: 1.791327e+09 | E36: =D36-D5 -> 33.748383 | F36: 1143 | G36: =(F36-F35)/$G$2/(D36-D35)*100 -> 10.849915
A37: 1 | B37: A | C37: 33 | D37: 1.791327e+09 | E37: =D37-D5 -> 34.8544 | F37: 1154 | G37: =(F37-F36)/$G$2/(D37-D36)*100 -> 9.9455944
A38: 1 | B38: A | C38: 34 | D38: 1.791327e+09 | E38: =D38-D5 -> 35.94612 | F38: 1173 | G38: =(F38-F37)/$G$2/(D38-D37)*100 -> 17.403732
A39: 1 | B39: A | C39: 35 | D39: 1.791327e+09 | E39: =D39-D5 -> 37.00787 | F39: 1190 | G39: =(F39-F38)/$G$2/(D39-D38)*100 -> 16.011307
A40: 1 | B40: A | C40: 36 | D40: 1.791327e+09 | E40: =D40-D5 -> 38.089713 | F40: 1202 | G40: =(F40-F39)/$G$2/(D40-D39)*100 -> 11.092179
A41: 1 | B41: A | C41: 37 | D41: 1.791327e+09 | E41: =D41-D5 -> 39.191395 | F41: 1213 | G41: =(F41-F40)/$G$2/(D41-D40)*100 -> 9.9847351
...

Sheet RSS
A1: Dados brutos de memória residente: VmRSS de /proc/<pid>/status a cada 10 amostras de CPU (~11 s), lido pelo shell do adb
A2: RSS (MB) = kB × 1024 ÷ 1.000.000 (megabytes decimais)
A4: Rodada | B4: Build | C4: Amostra | D4: Instante (s, relógio do aparelho) | E4: VmRSS (kB) | F4: RSS (MB)
A5: 1 | B5: A | C5: 1 | D5: 1.791327e+09 | E5: 229284 | F5: =E5*1024/1000000 -> 234.78682
A6: 1 | B6: A | C6: 2 | D6: 1.791327e+09 | E6: 243308 | F6: =E6*1024/1000000 -> 249.14739
A7: 1 | B7: A | C7: 3 | D7: 1.791327e+09 | E7: 235092 | F7: =E7*1024/1000000 -> 240.73421
A8: 1 | B8: A | C8: 4 | D8: 1.791327e+09 | E8: 248748 | F8: =E8*1024/1000000 -> 254.71795
A9: 1 | B9: A | C9: 5 | D9: 1.791327e+09 | E9: 237024 | F9: =E9*1024/1000000 -> 242.71258
A10: 1 | B10: A | C10: 6 | D10: 1.791327e+09 | E10: 230528 | F10: =E10*1024/1000000 -> 236.06067
A11: 1 | B11: A | C11: 7 | D11: 1.791327e+09 | E11: 243852 | F11: =E11*1024/1000000 -> 249.70445
A12: 1 | B12: A | C12: 8 | D12: 1.791327e+09 | E12: 230560 | F12: =E12*1024/1000000 -> 236.09344
A13: 1 | B13: A | C13: 9 | D13: 1.7913271e+09 | E13: 244244 | F13: =E13*1024/1000000 -> 250.10586
A14: 1 | B14: A | C14: 10 | D14: 1.7913271e+09 | E14: 241920 | F14: =E14*1024/1000000 -> 247.72608
A15: 1 | B15: A | C15: 11 | D15: 1.7913271e+09 | E15: 233328 | F15: =E15*1024/1000000 -> 238.92787
A16: 1 | B16: A | C16: 12 | D16: 1.7913271e+09 | E16: 247140 | F16: =E16*1024/1000000 -> 253.07136
... A112: 6 | B112: A | C112: 18 | D112: 1.791329e+09 | E112: 246704 | F112: =E112*1024/1000000 -> 252.6249

Sheet Método
A1: Método do teste de sobrecarga (A/B)
A3: Item | B3: Descrição
A4: Objetivo | B4: Medir de fora do app quanto CPU e memória a instrumentação (Sentry + coletor de 15 s) acrescenta, para responder ao efeito do observador.
A5: Aparelho | B5: Samsung Galaxy A54 5G, tela em 60 Hz (Suavidade de movimentos: Padrão), conectado por USB ao PC e carregando.
A6: Build A | B6: App sem medição: build local sem o DSN do Sentry. Sem DSN o Sentry fica inerte (não monta integrações nem inicializa o SDK nativo) e o coletor não liga. Ausência do DSN conferida no APK; cache do Metro limpo antes da build.
A7: Build B | B7: Build do experimento: Sentry com tracing a 100% + coletor de CPU, memória e FPS a cada 15 s (commit 14733be).
A8: Ordem | B8: A B A B B A (contrabalançada, para distribuir igualmente variações ao longo do tempo, como temperatura e bateria).
A9: Rodada | B9: Instalação da build; app fechado; 30 s de pausa; abertura a frio; 60 s de estabilização na lista de Pedidos; 180 amostras de CPU (~195 s) sem toque; PSS por dumpsys no fim.
A10: CPU | B10: /proc/<pid>/stat (utime + stime), a mesma fonte do top, lido pelo shell do adb, fora do app, a cada ~1,1 s (pausa de 1 s + leitura). A média da rodada divide os ticks pelo tempo real decorrido, então o intervalo não precisa ser exato.
A11: Memória | B11: VmRSS de /proc/<pid>/status a cada 10 amostras de CPU (~11 s); PSS total por dumpsys meminfo uma vez no fim (fora da janela de CPU, porque o dumpsys faz o app trabalhar).
A12: Validade | B12: Rodada válida se tiver ≥ 175 amostras de CPU, o mesmo PID do início ao fim e o app em primeiro plano. Na série final, só a rodada 3 foi repetida (a 1ª tentativa parou em 49 amostras). Duas séries anteriores, interrompidas pela perda do aparelho no adb, foram descartadas inteiras.
A13: Estatística | B13: Média e desvio padrão amostral por build; diferença B − A; teste t de Welch (variâncias desiguais), p bicaudal.
A14: Limitações | B14: 3 rodadas por build (poder estatístico baixo); medição externa só no Android, porque no iOS exigiria macOS; aparelho carregando pelo USB durante o teste.
A15: Observação operacional | B15: O servidor do adb no Windows perdeu o aparelho depois de ~10 min em algumas tentativas, mesmo com o USB ativo. Reiniciar o servidor resolveu, e o script passou a repetir rodadas inválidas.
